Workbook

Sheet my513300
A1: date | B1: time | C1: open | D1: high | E1: low | F1: close | G1: amount | H1: vol
A2: 45866 | B2: 0.39583333 | C2: 2.091 | D2: 2.096 | E2: 2.091 | F2: 2.094 | G2: 22923886 | H2: 109526
A3: 45866 | B3: 0.39652778 | C3: 2.093 | D3: 2.094 | E3: 2.093 | F3: 2.094 | G3: 9736332 | H3: 46504 | I3: 233.763332774921 | J3: =(#REF!-#REF!)*I3 -> #REF!
A4: 45866 | B4: 0.39722222 | C4: 2.094 | D4: 2.095 | E4: 2.094 | F4: 2.094 | G4: 2797761 | H4: 13360
A5: 45866 | B5: 0.39791667 | C5: 2.094 | D5: 2.095 | E5: 2.094 | F5: 2.095 | G5: 3775327 | H5: 18025
A6: 45866 | B6: 0.39861111 | C6: 2.095 | D6: 2.095 | E6: 2.094 | F6: 2.094 | G6: 1286874 | H6: 6145
A7: 45866 | B7: 0.39930556 | C7: 2.095 | D7: 2.095 | E7: 2.094 | F7: 2.094 | G7: 2944323 | H7: 14056
A8: 45866 | B8: 0.4 | C8: 2.094 | D8: 2.095 | E8: 2.094 | F8: 2.095 | G8: 3750444 | H8: 17904
A9: 45866 | B9: 0.40069444 | C9: 2.094 | D9: 2.095 | E9: 2.094 | F9: 2.094 | G9: 2415447 | H9: 11531
A10: 45866 | B10: 0.40138889 | C10: 2.094 | D10: 2.095 | E10: 2.094 | F10: 2.095 | G10: 8871363 | H10: 42347
A11: 45866 | B11: 0.40208333 | C11: 2.095 | D11: 2.096 | E11: 2.095 | F11: 2.096 | G11: 2024440 | H11: 9660
A12: 45866 | B12: 0.40277778 | C12: 2.096 | D12: 2.096 | E12: 2.095 | F12: 2.096 | G12: 1024229 | H12: 4887
A13: 45866 | B13: 0.40347222 | C13: 2.096 | D13: 2.096 | E13: 2.095 | F13: 2.095 | G13: 837401 | H13: 3996
A14: 45866 | B14: 0.40416667 | C14: 2.095 | D14: 2.096 | E14: 2.095 | F14: 2.095 | G14: 8093864 | H14: 38616
A15: 45866 | B15: 0.40486111 | C15: 2.096 | D15: 2.096 | E15: 2.095 | F15: 2.096 | G15: 528984 | H15: 2524
... A16081: 45966 | B16081: 0.62430556 | C16081: 2.367 | D16081: 2.367 | E16081: 2.365 | F16081: 2.366 | G16081: 2328662 | H16081: 9842

Sheet Sheet1
A1: 初始资金 | B1: 初始持仓 | C1: 基准价 | D1: 佣金 | E1: 最低佣金 | G1: 上涨百分比 | H1: 下跌百分比 | I1: 上涨差价 | J1: 下跌差价 | K1: 涨卖出股数 | L1: 跌买入股数
A2: 12000 | B2: 0 | C2: ='my513300'!F15842 -> 2.319 | D2: 5e-05 | E2: 0.1 | G2: 0.001 | H2: 0.001 | K2: 400 | L2: =K2 -> 400
A3: 买入总价格 | B3: 卖出总价格 | C3: 买入手续费 | D3: 卖出手续费
A4: {=SUMPRODUCT('11.5'!M2:M241,'11.5'!O2:O241)} -> 16875.6 | B4: {=SUMPRODUCT('11.5'!N2:N241,'11.5'!P2:P241)} -> 15972 | C4: =SUM('11.5'!Q:Q) -> 1.8 | D4: =SUM('11.5'!R:R) -> 1.7
A6: profit | C6: 买入总股数 | D6: 卖入总股数
A7: =B4-A4-C4-D4 -> -907.1 | C7: =SUM('11.5'!M:M) -> 7200 | D7: =SUM('11.5'!N:N) -> 6800
A9: =A7/A2 -> -0.075591667

Sheet 11.5
A1: date | B1: time | C1: open | D1: high | E1: low | F1: close | G1: amount | H1: vol | J1: drop or rise | K1: drop or rise precent | M1: buy precent | N1: sell present | O1: buy point | P1: sell point | Q1: buy手续费 | R1: sell手续费 | T1: buy price | U1: sell price
A2: 45966 | B2: 0.39583333 | C2: 2.311 | D2: 2.324 | E2: 2.311 | F2: 2.319 | G2: 75257632 | H2: 325270 | J2: 0 | K2: 0 | M2: 0 | N2: 0 | O2: =IF(M2=0,"",F2) | Q2: =IF(O2="",0,IF(M2*O2*Sheet1!$D$2<Sheet1!$E$2,Sheet1!$E$2,M2*O2*Sheet1!$D$2)) -> 0 | R2: =IF(P2="",0,IF(P2*N2*Sheet1!$D$2<Sheet1!$E$2,Sheet1!$E$2,P2*N2*Sheet1!$D$2)) -> 0 | T2: 0 | U2: 0
A3: 45966 | B3: 0.39652778 | C3: 2.321 | D3: 2.326 | E3: 2.319 | F3: 2.319 | G3: 18437612 | H3: 79372 | J3: =F3-F2 -> 0 | K3: =(F3-F2)/F2 -> 0 | L3: =IF(K3>Sheet1!$G$2,IF(Sheet1!$B$2+SUM($M$2:M2)-SUM($N$2:N2)-Sheet1!$K$2>=0,Sheet1!$K$2,0),0) -> 0 | M3: {=IF(K3<-Sheet1!$H$2,IF(Sheet1!$A$2+SUMPRODUCT($F$2:F2,$N$2:N2)-SUMPRODUCT($F$2:F2,$M$2:M2)-$F$3*Sheet1!$L$2>=0,Sheet1!$L$2,0),0)} -> 0 | N3: =IF(K3>Sheet1!$G$2,IF(Sheet1!$B$2+SUM($M$2:M2)-SUM($N$2:N2)-Sheet1!$K$2>=0,Sheet1!$K$2,0),0) -> 0 | O3: =IF(M3=0,"",F3) | P3: =IF(N3=0,"",F3) | Q3: =IF(O3="",0,IF(M3*O3*Sheet1!$D$2<Sheet1!$E$2,Sheet1!$E$2,M3*O3*Sheet1!$D$2)) -> 0 | R3: =IF(P3="",0,IF(P3*N3*Sheet1!$D$2<Sheet1!$E$2,Sheet1!$E$2,P3*N3*Sheet1!$D$2)) -> 0
A4: 45966 | B4: 0.39722222 | C4: 2.319 | D4: 2.322 | E4: 2.319 | F4: 2.321 | G4: 20093358 | H4: 86618 | J4: =F4-F3 -> 0.002 | K4: =(F4-F3)/F3 -> 0.00086244071 | L4: =IF(K4>Sheet1!$G$2,IF(Sheet1!$B$2+SUM($M$2:M3)-SUM($N$2:N3)-Sheet1!$K$2>=0,Sheet1!$K$2,0),0) -> 0 | M4: {=IF(K4<-Sheet1!$H$2,IF(Sheet1!$A$2+SUMPRODUCT($F$2:F3,$N$2:N3)-SUMPRODUCT($F$2:F3,$M$2:M3)-$F$3*Sheet1!$L$2>=0,Sheet1!$L$2,0),0)} -> 0 | N4: =IF(K4>Sheet1!$G$2,IF(Sheet1!$B$2+SUM($M$2:M3)-SUM($N$2:N3)-Sheet1!$K$2>=0,Sheet1!$K$2,0),0) -> 0 | O4: =IF(M4=0,"",F4) | P4: =IF(N4=0,"",F4) | Q4: =IF(O4="",0,IF(M4*O4*Sheet1!$D$2<Sheet1!$E$2,Sheet1!$E$2,M4*O4*Sheet1!$D$2)) -> 0 | R4: =IF(P4="",0,IF(P4*N4*Sheet1!$D$2<Sheet1!$E$2,Sheet1!$E$2,P4*N4*Sheet1!$D$2)) -> 0
A5: 45966 | B5: 0.39791667 | C5: 2.321 | D5: 2.336 | E5: 2.32 | F5: 2.33 | G5: 29883600 | H5: 128570 | J5: =F5-F4 -> 0.009 | K5: =(F5-F4)/F4 -> 0.0038776389 | L5: =IF(K5>Sheet1!$G$2,IF(Sheet1!$B$2+SUM($M$2:M4)-SUM($N$2:N4)-Sheet1!$K$2>=0,Sheet1!$K$2,0),0) -> 0 | M5: {=IF(K5<-Sheet1!$H$2,IF(Sheet1!$A$2+SUMPRODUCT($F$2:F4,$N$2:N4)-SUMPRODUCT($F$2:F4,$M$2:M4)-$F$3*Sheet1!$L$2>=0,Sheet1!$L$2,0),0)} -> 0 | N5: =IF(K5>Sheet1!$G$2,IF(Sheet1!$B$2+SUM($M$2:M4)-SUM($N$2:N4)-Sheet1!$K$2>=0,Sheet1!$K$2,0),0) -> 0 | O5: =IF(M5=0,"",F5) | P5: =IF(N5=0,"",F5) | Q5: =IF(O5="",0,IF(M5*O5*Sheet1!$D$2<Sheet1!$E$2,Sheet1!$E$2,M5*O5*Sheet1!$D$2)) -> 0 | R5: =IF(P5="",0,IF(P5*N5*Sheet1!$D$2<Sheet1!$E$2,Sheet1!$E$2,P5*N5*Sheet1!$D$2)) -> 0
A6: 45966 | B6: 0.39861111 | C6: 2.328 | D6: 2.329 | E6: 2.325 | F6: 2.325 | G6: 14470292 | H6: 62173 | J6: =F6-F5 -> -0.005 | K6: =(F6-F5)/F5 -> -0.0021459227 | L6: =IF(K6>Sheet1!$G$2,IF(Sheet1!$B$2+SUM($M$2:M5)-SUM($N$2:N5)-Sheet1!$K$2>=0,Sheet1!$K$2,0),0) -> 0 | M6: {=IF(K6<-Sheet1!$H$2,IF(Sheet1!$A$2+SUMPRODUCT($F$2:F5,$N$2:N5)-SUMPRODUCT($F$2:F5,$M$2:M5)-$F$3*Sheet1!$L$2>=0,Sheet1!$L$2,0),0)} -> 400 | N6: =IF(K6>Sheet1!$G$2,IF(Sheet1!$B$2+SUM($M$2:M5)-SUM($N$2:N5)-Sheet1!$K$2>=0,Sheet1!$K$2,0),0) -> 0 | O6: =IF(M6=0,"",F6) -> 2.325 | P6: =IF(N6=0,"",F6) | Q6: =IF(O6="",0,IF(M6*O6*Sheet1!$D$2<Sheet1!$E$2,Sheet1!$E$2,M6*O6*Sheet1!$D$2)) -> 0.1 | R6: =IF(P6="",0,IF(P6*N6*Sheet1!$D$2<Sheet1!$E$2,Sheet1!$E$2,P6*N6*Sheet1!$D$2)) -> 0
A7: 45966 | B7: 0.39930556 | C7: 2.325 | D7: 2.33 | E7: 2.325 | F7: 2.33 | G7: 13804045 | H7: 59310 | J7: =F7-F6 -> 0.005 | K7: =(F7-F6)/F6 -> 0.0021505376 | L7: =IF(K7>Sheet1!$G$2,IF(Sheet1!$B$2+SUM($M$2:M6)-SUM($N$2:N6)-Sheet1!$K$2>=0,Sheet1!$K$2,0),0) -> 400 | M7: {=IF(K7<-Sheet1!$H$2,IF(Sheet1!$A$2+SUMPRODUCT($F$2:F6,$N$2:N6)-SUMPRODUCT($F$2:F6,$M$2:M6)-$F$3*Sheet1!$L$2>=0,Sheet1!$L$2,0),0)} -> 0 | N7: =IF(K7>Sheet1!$G$2,IF(Sheet1!$B$2+SUM($M$2:M6)-SUM($N$2:N6)-Sheet1!$K$2>=0,Sheet1!$K$2,0),0) -> 400 | O7: =IF(M7=0,"",F7) | P7: =IF(N7=0,"",F7) -> 2.33 | Q7: =IF(O7="",0,IF(M7*O7*Sheet1!$D$2<Sheet1!$E$2,Sheet1!$E$2,M7*O7*Sheet1!$D$2)) -> 0 | R7: =IF(P7="",0,IF(P7*N7*Sheet1!$D$2<Sheet1!$E$2,Sheet1!$E$2,P7*N7*Sheet1!$D$2)) -> 0.1
A8: 45966 | B8: 0.4 | C8: 2.33 | D8: 2.335 | E8: 2.33 | F8: 2.333 | G8: 12579481 | H8: 53931 | J8: =F8-F7 -> 0.003 | K8: =(F8-F7)/F7 -> 0.0012875536 | L8: =IF(K8>Sheet1!$G$2,IF(Sheet1!$B$2+SUM($M$2:M7)-SUM($N$2:N7)-Sheet1!$K$2>=0,Sheet1!$K$2,0),0) -> 0 | M8: {=IF(K8<-Sheet1!$H$2,IF(Sheet1!$A$2+SUMPRODUCT($F$2:F7,$N$2:N7)-SUMPRODUCT($F$2:F7,$M$2:M7)-$F$3*Sheet1!$L$2>=0,Sheet1!$L$2,0),0)} -> 0 | N8: =IF(K8>Sheet1!$G$2,IF(Sheet1!$B$2+SUM($M$2:M7)-SUM($N$2:N7)-Sheet1!$K$2>=0,Sheet1!$K$2,0),0) -> 0 | O8: =IF(M8=0,"",F8) | P8: =IF(N8=0,"",F8) | Q8: =IF(O8="",0,IF(M8*O8*Sheet1!$D$2<Sheet1!$E$2,Sheet1!$E$2,M8*O8*Sheet1!$D$2)) -> 0 | R8: =IF(P8="",0,IF(P8*N8*Sheet1!$D$2<Sheet1!$E$2,Sheet1!$E$2,P8*N8*Sheet1!$D$2)) -> 0
A9: 45966 | B9: 0.40069444 | C9: 2.332 | D9: 2.332 | E9: 2.327 | F9: 2.33 | G9: 9319614 | H9: 40017 | J9: =F9-F8 -> -0.003 | K9: =(F9-F8)/F8 -> -0.001285898 | L9: =IF(K9>Sheet1!$G$2,IF(Sheet1!$B$2+SUM($M$2:M8)-SUM($N$2:N8)-Sheet1!$K$2>=0,Sheet1!$K$2,0),0) -> 0 | M9: {=IF(K9<-Sheet1!$H$2,IF(Sheet1!$A$2+SUMPRODUCT($F$2:F8,$N$2:N8)-SUMPRODUCT($F$2:F8,$M$2:M8)-$F$3*Sheet1!$L$2>=0,Sheet1!$L$2,0),0)} -> 400 | N9: =IF(K9>Sheet1!$G$2,IF(Sheet1!$B$2+SUM($M$2:M8)-SUM($N$2:N8)-Sheet1!$K$2>=0,Sheet1!$K$2,0),0) -> 0 | O9: =IF(M9=0,"",F9) -> 2.33 | P9: =IF(N9=0,"",F9) | Q9: =IF(O9="",0,IF(M9*O9*Sheet1!$D$2<Sheet1!$E$2,Sheet1!$E$2,M9*O9*Sheet1!$D$2)) -> 0.1 | R9: =IF(P9="",0,IF(P9*N9*Sheet1!$D$2<Sheet1!$E$2,Sheet1!$E$2,P9*N9*Sheet1!$D$2)) -> 0
A10: 45966 | B10: 0.40138889 | C10: 2.33 | D10: 2.33 | E10: 2.328 | F10: 2.329 | G10: 3800146 | H10: 16317 | J10: =F10-F9 -> -0.001 | K10: =(F10-F9)/F9 -> -0.00042918455 | L10: =IF(K10>Sheet1!$G$2,IF(Sheet1!$B$2+SUM($M$2:M9)-SUM($N$2:N9)-Sheet1!$K$2>=0,Sheet1!$K$2,0),0) -> 0 | M10: {=IF(K10<-Sheet1!$H$2,IF(Sheet1!$A$2+SUMPRODUCT($F$2:F9,$N$2:N9)-SUMPRODUCT($F$2:F9,$M$2:M9)-$F$3*Sheet1!$L$2>=0,Sheet1!$L$2,0),0)} -> 0 | N10: =IF(K10>Sheet1!$G$2,IF(Sheet1!$B$2+SUM($M$2:M9)-SUM($N$2:N9)-Sheet1!$K$2>=0,Sheet1!$K$2,0),0) -> 0 | O10: =IF(M10=0,"",F10) | P10: =IF(N10=0,"",F10) | Q10: =IF(O10="",0,IF(M10*O10*Sheet1!$D$2<Sheet1!$E$2,Sheet1!$E$2,M10*O10*Sheet1!$D$2)) -> 0 | R10: =IF(P10="",0,IF(P10*N10*Sheet1!$D$2<Sheet1!$E$2,Sheet1!$E$2,P10*N10*Sheet1!$D$2)) -> 0
A11: 45966 | B11: 0.40208333 | C11: 2.329 | D11: 2.331 | E11: 2.328 | F11: 2.329 | G11: 9135887 | H11: 39218 | J11: =F11-F10 -> 0 | K11: =(F11-F10)/F10 -> 0 | L11: =IF(K11>Sheet1!$G$2,IF(Sheet1!$B$2+SUM($M$2:M10)-SUM($N$2:N10)-Sheet1!$K$2>=0,Sheet1!$K$2,0),0) -> 0 | M11: {=IF(K11<-Sheet1!$H$2,IF(Sheet1!$A$2+SUMPRODUCT($F$2:F10,$N$2:N10)-SUMPRODUCT($F$2:F10,$M$2:M10)-$F$3*Sheet1!$L$2>=0,Sheet1!$L$2,0),0)} -> 0 | N11: =IF(K11>Sheet1!$G$2,IF(Sheet1!$B$2+SUM($M$2:M10)-SUM($N$2:N10)-Sheet1!$K$2>=0,Sheet1!$K$2,0),0) -> 0 | O11: =IF(M11=0,"",F11) | P11: =IF(N11=0,"",F11) | Q11: =IF(O11="",0,IF(M11*O11*Sheet1!$D$2<Sheet1!$E$2,Sheet1!$E$2,M11*O11*Sheet1!$D$2)) -> 0 | R11: =IF(P11="",0,IF(P11*N11*Sheet1!$D$2<Sheet1!$E$2,Sheet1!$E$2,P11*N11*Sheet1!$D$2)) -> 0
A12: 45966 | B12: 0.40277778 | C12: 2.329 | D12: 2.329 | E12: 2.325 | F12: 2.325 | G12: 7689904 | H12: 33050 | J12: =F12-F11 -> -0.004 | K12: =(F12-F11)/F11 -> -0.0017174753 | L12: =IF(K12>Sheet1!$G$2,IF(Sheet1!$B$2+SUM($M$2:M11)-SUM($N$2:N11)-Sheet1!$K$2>=0,Sheet1!$K$2,0),0) -> 0 | M12: {=IF(K12<-Sheet1!$H$2,IF(Sheet1!$A$2+SUMPRODUCT($F$2:F11,$N$2:N11)-SUMPRODUCT($F$2:F11,$M$2:M11)-$F$3*Sheet1!$L$2>=0,Sheet1!$L$2,0),0)} -> 400 | N12: =IF(K12>Sheet1!$G$2,IF(Sheet1!$B$2+SUM($M$2:M11)-SUM($N$2:N11)-Sheet1!$K$2>=0,Sheet1!$K$2,0),0) -> 0 | O12: =IF(M12=0,"",F12) -> 2.325 | P12: =IF(N12=0,"",F12) | Q12: =IF(O12="",0,IF(M12*O12*Sheet1!$D$2<Sheet1!$E$2,Sheet1!$E$2,M12*O12*Sheet1!$D$2)) -> 0.1 | R12: =IF(P12="",0,IF(P12*N12*Sheet1!$D$2<Sheet1!$E$2,Sheet1!$E$2,P12*N12*Sheet1!$D$2)) -> 0
A13: 45966 | B13: 0.40347222 | C13: 2.325 | D13: 2.331 | E13: 2.325 | F13: 2.329 | G13: 8725084 | H13: 37488 | J13: =F13-F12 -> 0.004 | K13: =(F13-F12)/F12 -> 0.0017204301 | L13: =IF(K13>Sheet1!$G$2,IF(Sheet1!$B$2+SUM($M$2:M12)-SUM($N$2:N12)-Sheet1!$K$2>=0,Sheet1!$K$2,0),0) -> 400 | M13: {=IF(K13<-Sheet1!$H$2,IF(Sheet1!$A$2+SUMPRODUCT($F$2:F12,$N$2:N12)-SUMPRODUCT($F$2:F12,$M$2:M12)-$F$3*Sheet1!$L$2>=0,Sheet1!$L$2,0),0)} -> 0 | N13: =IF(K13>Sheet1!$G$2,IF(Sheet1!$B$2+SUM($M$2:M12)-SUM($N$2:N12)-Sheet1!$K$2>=0,Sheet1!$K$2,0),0) -> 400 | O13: =IF(M13=0,"",F13) | P13: =IF(N13=0,"",F13) -> 2.329 | Q13: =IF(O13="",0,IF(M13*O13*Sheet1!$D$2<Sheet1!$E$2,Sheet1!$E$2,M13*O13*Sheet1!$D$2)) -> 0 | R13: =IF(P13="",0,IF(P13*N13*Sheet1!$D$2<Sheet1!$E$2,Sheet1!$E$2,P13*N13*Sheet1!$D$2)) -> 0.1
A14: 45966 | B14: 0.40416667 | C14: 2.331 | D14: 2.331 | E14: 2.329 | F14: 2.329 | G14: 3064143 | H14: 13151 | J14: =F14-F13 -> 0 | K14: =(F14-F13)/F13 -> 0 | L14: =IF(K14>Sheet1!$G$2,IF(Sheet1!$B$2+SUM($M$2:M13)-SUM($N$2:N13)-Sheet1!$K$2>=0,Sheet1!$K$2,0),0) -> 0 | M14: {=IF(K14<-Sheet1!$H$2,IF(Sheet1!$A$2+SUMPRODUCT($F$2:F13,$N$2:N13)-SUMPRODUCT($F$2:F13,$M$2:M13)-$F$3*Sheet1!$L$2>=0,Sheet1!$L$2,0),0)} -> 0 | N14: =IF(K14>Sheet1!$G$2,IF(Sheet1!$B$2+SUM($M$2:M13)-SUM($N$2:N13)-Sheet1!$K$2>=0,Sheet1!$K$2,0),0) -> 0 | O14: =IF(M14=0,"",F14) | P14: =IF(N14=0,"",F14) | Q14: =IF(O14="",0,IF(M14*O14*Sheet1!$D$2<Sheet1!$E$2,Sheet1!$E$2,M14*O14*Sheet1!$D$2)) -> 0 | R14: =IF(P14="",0,IF(P14*N14*Sheet1!$D$2<Sheet1!$E$2,Sheet1!$E$2,P14*N14*Sheet1!$D$2)) -> 0
... A42: 45966 | B42: 0.42361111 | C42: 2.329 | D42: 2.329 | E42: 2.328 | F42: 2.328 | G42: 2671823 | H42: 11476 | J42: =F42-F41 -> -0.001 | K42: =(F42-F41)/F41 -> -0.00042936883 | L42: =IF(K42>Sheet1!$G$2,IF(Sheet1!$B$2+SUM($M$2:M41)-SUM($N$2:N41)-Sheet1!$K$2>=0,Sheet1!$K$2,0),0) -> 0 | M42: {=IF(K42<-Sheet1!$H$2,IF(Sheet1!$A$2+SUMPRODUCT($F$2:F41,$N$2:N41)-SUMPRODUCT($F$2:F41,$M$2:M41)-$F$3*Sheet1!$L$2>=0,Sheet1!$L$2,0),0)} -> 0 | N42: =IF(K42>Sheet1!$G$2,IF(Sheet1!$B$2+SUM($M$2:M41)-SUM($N$2:N41)-Sheet1!$K$2>=0,Sheet1!$K$2,0),0) -> 0 | O42: =IF(M42=0,"",F42) | P42: =IF(N42=0,"",F42) | Q42: =IF(O42="",0,IF(M42*O42*Sheet1!$D$2<Sheet1!$E$2,Sheet1!$E$2,M42*O42*Sheet1!$D$2)) -> 0 | R42: =IF(P42="",0,IF(P42*N42*Sheet1!$D$2<Sheet1!$E$2,Sheet1!$E$2,P42*N42*Sheet1!$D$2)) -> 0
A43: 45966 | B43: 0.42430556 | C43: 2.328 | D43: 2.328 | E43: 2.327 | F43: 2.328 | G43: 1211369 | H43: 5204 | J43: =F43-F42 -> 0 | K43: =(F43-F42)/F42 -> 0 | L43: =IF(K43>Sheet1!$G$2,IF(Sheet1!$B$2+SUM($M$2:M42)-Sheet1!$K$2>=0,Sheet1!$K$2,0),0) -> 0 | M43: {=IF(K43<-Sheet1!$H$2,IF(Sheet1!$A$2+SUMPRODUCT($F$2:F42,$N$2:N42)-SUMPRODUCT($F$2:F42,$M$2:M42)-$F$3*Sheet1!$L$2>=0,Sheet1!$L$2,0),0)} -> 0 | N43: =IF(K43>Sheet1!$G$2,IF(Sheet1!$B$2+SUM($M$2:M42)-SUM($N$2:N42)-Sheet1!$K$2>=0,Sheet1!$K$2,0),0) -> 0 | O43: =IF(M43=0,"",F43) | P43: =IF(N43=0,"",F43) | Q43: =IF(O43="",0,IF(M43*O43*Sheet1!$D$2<Sheet1!$E$2,Sheet1!$E$2,M43*O43*Sheet1!$D$2)) -> 0 | R43: =IF(P43="",0,IF(P43*N43*Sheet1!$D$2<Sheet1!$E$2,Sheet1!$E$2,P43*N43*Sheet1!$D$2)) -> 0
A44: 45966 | B44: 0.425 | C44: 2.328 | D44: 2.328 | E44: 2.327 | F44: 2.328 | G44: 1034231 | H44: 4444 | J44: =F44-F43 -> 0 | K44: =(F44-F43)/F43 -> 0 | L44: =IF(K44>Sheet1!$G$2,IF(Sheet1!$B$2+SUM($M$2:M43)-Sheet1!$K$2>=0,Sheet1!$K$2,0),0) -> 0 | M44: {=IF(K44<-Sheet1!$H$2,IF(Sheet1!$A$2+SUMPRODUCT($F$2:F43,$N$2:N43)-SUMPRODUCT($F$2:F43,$M$2:M43)-$F$3*Sheet1!$L$2>=0,Sheet1!$L$2,0),0)} -> 0 | N44: =IF(K44>Sheet1!$G$2,IF(Sheet1!$B$2+SUM($M$2:M43)-SUM($N$2:N43)-Sheet1!$K$2>=0,Sheet1!$K$2,0),0) -> 0 | O44: =IF(M44=0,"",F44) | P44: =IF(N44=0,"",F44) | Q44: =IF(O44="",0,IF(M44*O44*Sheet1!$D$2<Sheet1!$E$2,Sheet1!$E$2,M44*O44*Sheet1!$D$2)) -> 0 | R44: =IF(P44="",0,IF(P44*N44*Sheet1!$D$2<Sheet1!$E$2,Sheet1!$E$2,P44*N44*Sheet1!$D$2)) -> 0
A45: 45966 | B45: 0.42569444 | C45: 2.328 | D45: 2.328 | E45: 2.326 | F45: 2.326 | G45: 4627661 | H45: 19889 | J45: =F45-F44 -> -0.002 | K45: =(F45-F44)/F44 -> -0.00085910653 | L45: =IF(K45>Sheet1!$G$2,IF(Sheet1!$B$2+SUM($M$2:M44)-Sheet1!$K$2>=0,Sheet1!$K$2,0),0) -> 0 | M45: {=IF(K45<-Sheet1!$H$2,IF(Sheet1!$A$2+SUMPRODUCT($F$2:F44,$N$2:N44)-SUMPRODUCT($F$2:F44,$M$2:M44)-$F$3*Sheet1!$L$2>=0,Sheet1!$L$2,0),0)} -> 0 | N45: =IF(K45>Sheet1!$G$2,IF(Sheet1!$B$2+SUM($M$2:M44)-SUM($N$2:N44)-Sheet1!$K$2>=0,Sheet1!$K$2,0),0) -> 0 | O45: =IF(M45=0,"",F45) | P45: =IF(N45=0,"",F45) | Q45: =IF(O45="",0,IF(M45*O45*Sheet1!$D$2<Sheet1!$E$2,Sheet1!$E$2,M45*O45*Sheet1!$D$2)) -> 0 | R45: =IF(P45="",0,IF(P45*N45*Sheet1!$D$2<Sheet1!$E$2,Sheet1!$E$2,P45*N45*Sheet1!$D$2)) -> 0
A46: 45966 | B46: 0.42638889 | C46: 2.327 | D46: 2.327 | E46: 2.325 | F46: 2.326 | G46: 6044344 | H46: 25983 | J46: =F46-F45 -> 0 | K46: =(F46-F45)/F45 -> 0 | L46: =IF(K46>Sheet1!$G$2,IF(Sheet1!$B$2+SUM($M$2:M45)-Sheet1!$K$2>=0,Sheet1!$K$2,0),0) -> 0 | M46: {=IF(K46<-Sheet1!$H$2,IF(Sheet1!$A$2+SUMPRODUCT($F$2:F45,$N$2:N45)-SUMPRODUCT($F$2:F45,$M$2:M45)-$F$3*Sheet1!$L$2>=0,Sheet1!$L$2,0),0)} -> 0 | N46: =IF(K46>Sheet1!$G$2,IF(Sheet1!$B$2+SUM($M$2:M45)-SUM($N$2:N45)-Sheet1!$K$2>=0,Sheet1!$K$2,0),0) -> 0 | O46: =IF(M46=0,"",F46) | P46: =IF(N46=0,"",F46) | Q46: =IF(O46="",0,IF(M46*O46*Sheet1!$D$2<Sheet1!$E$2,Sheet1!$E$2,M46*O46*Sheet1!$D$2)) -> 0 | R46: =IF(P46="",0,IF(P46*N46*Sheet1!$D$2<Sheet1!$E$2,Sheet1!$E$2,P46*N46*Sheet1!$D$2)) -> 0
A47: 45966 | B47: 0.42708333 | C47: 2.326 | D47: 2.326 | E47: 2.325 | F47: 2.325 | G47: 1311318 | H47: 5639 | J47: =F47-F46 -> -0.001 | K47: =(F47-F46)/F46 -> -0.00042992261 | L47: =IF(K47>Sheet1!$G$2,IF(Sheet1!$B$2+SUM($M$2:M46)-Sheet1!$K$2>=0,Sheet1!$K$2,0),0) -> 0 | M47: {=IF(K47<-Sheet1!$H$2,IF(Sheet1!$A$2+SUMPRODUCT($F$2:F46,$N$2:N46)-SUMPRODUCT($F$2:F46,$M$2:M46)-$F$3*Sheet1!$L$2>=0,Sheet1!$L$2,0),0)} -> 0 | N47: =IF(K47>Sheet1!$G$2,IF(Sheet1!$B$2+SUM($M$2:M46)-SUM($N$2:N46)-Sheet1!$K$2>=0,Sheet1!$K$2,0),0) -> 0 | O47: =IF(M47=0,"",F47) | P47: =IF(N47=0,"",F47) | Q47: =IF(O47="",0,IF(M47*O47*Sheet1!$D$2<Sheet1!$E$2,Sheet1!$E$2,M47*O47*Sheet1!$D$2)) -> 0 | R47: =IF(P47="",0,IF(P47*N47*Sheet1!$D$2<Sheet1!$E$2,Sheet1!$E$2,P47*N47*Sheet1!$D$2)) -> 0
A48: 45966 | B48: 0.42777778 | C48: 2.326 | D48: 2.326 | E48: 2.325 | F48: 2.325 | G48: 1347010 | H48: 5793 | J48: =F48-F47 -> 0 | K48: =(F48-F47)/F47 -> 0 | L48: =IF(K48>Sheet1!$G$2,IF(Sheet1!$B$2+SUM($M$2:M47)-Sheet1!$K$2>=0,Sheet1!$K$2,0),0) -> 0 | M48: {=IF(K48<-Sheet1!$H$2,IF(Sheet1!$A$2+SUMPRODUCT($F$2:F47,$N$2:N47)-SUMPRODUCT($F$2:F47,$M$2:M47)-$F$3*Sheet1!$L$2>=0,Sheet1!$L$2,0),0)} -> 0 | N48: =IF(K48>Sheet1!$G$2,IF(Sheet1!$B$2+SUM($M$2:M47)-SUM($N$2:N47)-Sheet1!$K$2>=0,Sheet1!$K$2,0),0) -> 0 | O48: =IF(M48=0,"",F48) | P48: =IF(N48=0,"",F48) | Q48: =IF(O48="",0,IF(M48*O48*Sheet1!$D$2<Sheet1!$E$2,Sheet1!$E$2,M48*O48*Sheet1!$D$2)) -> 0 | R48: =IF(P48="",0,IF(P48*N48*Sheet1!$D$2<Sheet1!$E$2,Sheet1!$E$2,P48*N48*Sheet1!$D$2)) -> 0
A49: 45966 | B49: 0.42847222 | C49: 2.326 | D49: 2.326 | E49: 2.325 | F49: 2.326 | G49: 1658866 | H49: 7132 | J49: =F49-F48 -> 0.001 | K49: =(F49-F48)/F48 -> 0.00043010753 | L49: =IF(K49>Sheet1!$G$2,IF(Sheet1!$B$2+SUM($M$2:M48)-Sheet1!$K$2>=0,Sheet1!$K$2,0),0) -> 0 | M49: {=IF(K49<-Sheet1!$H$2,IF(Sheet1!$A$2+SUMPRODUCT($F$2:F48,$N$2:N48)-SUMPRODUCT($F$2:F48,$M$2:M48)-$F$3*Sheet1!$L$2>=0,Sheet1!$L$2,0),0)} -> 0 | N49: =IF(K49>Sheet1!$G$2,IF(Sheet1!$B$2+SUM($M$2:M48)-SUM($N$2:N48)-Sheet1!$K$2>=0,Sheet1!$K$2,0),0) -> 0 | O49: =IF(M49=0,"",F49) | P49: =IF(N49=0,"",F49) | Q49: =IF(O49="",0,IF(M49*O49*Sheet1!$D$2<Sheet1!$E$2,Sheet1!$E$2,M49*O49*Sheet1!$D$2)) -> 0 | R49: =IF(P49="",0,IF(P49*N49*Sheet1!$D$2<Sheet1!$E$2,Sheet1!$E$2,P49*N49*Sheet1!$D$2)) -> 0
A50: 45966 | B50: 0.42916667 | C50: 2.326 | D50: 2.326 | E50: 2.325 | F50: 2.325 | G50: 971512 | H50: 4177 | J50: =F50-F49 -> -0.001 | K50: =(F50-F49)/F49 -> -0.00042992261 | L50: =IF(K50>Sheet1!$G$2,IF(Sheet1!$B$2+SUM($M$2:M49)-Sheet1!$K$2>=0,Sheet1!$K$2,0),0) -> 0 | M50: {=IF(K50<-Sheet1!$H$2,IF(Sheet1!$A$2+SUMPRODUCT($F$2:F49,$N$2:N49)-SUMPRODUCT($F$2:F49,$M$2:M49)-$F$3*Sheet1!$L$2>=0,Sheet1!$L$2,0),0)} -> 0 | N50: =IF(K50>Sheet1!$G$2,IF(Sheet1!$B$2+SUM($M$2:M49)-SUM($N$2:N49)-Sheet1!$K$2>=0,Sheet1!$K$2,0),0) -> 0 | O50: =IF(M50=0,"",F50) | P50: =IF(N50=0,"",F50) | Q50: =IF(O50="",0,IF(M50*O50*Sheet1!$D$2<Sheet1!$E$2,Sheet1!$E$2,M50*O50*Sheet1!$D$2)) -> 0 | R50: =IF(P50="",0,IF(P50*N50*Sheet1!$D$2<Sheet1!$E$2,Sheet1!$E$2,P50*N50*Sheet1!$D$2)) -> 0
A51: 45966 | B51: 0.42986111 | C51: 2.325 | D51: 2.326 | E51: 2.325 | F51: 2.326 | G51: 1415970 | H51: 6088 | J51: =F51-F50 -> 0.001 | K51: =(F51-F50)/F50 -> 0.00043010753 | L51: =IF(K51>Sheet1!$G$2,IF(Sheet1!$B$2+SUM($M$2:M50)-Sheet1!$K$2>=0,Sheet1!$K$2,0),0) -> 0 | M51: {=IF(K51<-Sheet1!$H$2,IF(Sheet1!$A$2+SUMPRODUCT($F$2:F50,$N$2:N50)-SUMPRODUCT($F$2:F50,$M$2:M50)-$F$3*Sheet1!$L$2>=0,Sheet1!$L$2,0),0)} -> 0 | N51: =IF(K51>Sheet1!$G$2,IF(Sheet1!$B$2+SUM($M$2:M50)-SUM($N$2:N50)-Sheet1!$K$2>=0,Sheet1!$K$2,0),0) -> 0 | O51: =IF(M51=0,"",F51) | P51: =IF(N51=0,"",F51) | Q51: =IF(O51="",0,IF(M51*O51*Sheet1!$D$2<Sheet1!$E$2,Sheet1!$E$2,M51*O51*Sheet1!$D$2)) -> 0 | R51: =IF(P51="",0,IF(P51*N51*Sheet1!$D$2<Sheet1!$E$2,Sheet1!$E$2,P51*N51*Sheet1!$D$2)) -> 0
A52: 45966 | B52: 0.43055556 | C52: 2.326 | D52: 2.327 | E52: 2.325 | F52: 2.327 | G52: 6470486 | H52: 27812 | J52: =F52-F51 -> 0.001 | K52: =(F52-F51)/F51 -> 0.00042992261 | L52: =IF(K52>Sheet1!$G$2,IF(Sheet1!$B$2+SUM($M$2:M51)-Sheet1!$K$2>=0,Sheet1!$K$2,0),0) -> 0 | M52: {=IF(K52<-Sheet1!$H$2,IF(Sheet1!$A$2+SUMPRODUCT($F$2:F51,$N$2:N51)-SUMPRODUCT($F$2:F51,$M$2:M51)-$F$3*Sheet1!$L$2>=0,Sheet1!$L$2,0),0)} -> 0 | N52: =IF(K52>Sheet1!$G$2,IF(Sheet1!$B$2+SUM($M$2:M51)-SUM($N$2:N51)-Sheet1!$K$2>=0,Sheet1!$K$2,0),0) -> 0 | O52: =IF(M52=0,"",F52) | P52: =IF(N52=0,"",F52) | Q52: =IF(O52="",0,IF(M52*O52*Sheet1!$D$2<Sheet1!$E$2,Sheet1!$E$2,M52*O52*Sheet1!$D$2)) -> 0 | R52: =IF(P52="",0,IF(P52*N52*Sheet1!$D$2<Sheet1!$E$2,Sheet1!$E$2,P52*N52*Sheet1!$D$2)) -> 0
A53: 45966 | B53: 0.43125 | C53: 2.327 | D53: 2.328 | E53: 2.326 | F53: 2.328 | G53: 1213546 | H53: 5215 | J53: =F53-F52 -> 0.001 | K53: =(F53-F52)/F52 -> 0.00042973786 | L53: =IF(K53>Sheet1!$G$2,IF(Sheet1!$B$2+SUM($M$2:M52)-Sheet1!$K$2>=0,Sheet1!$K$2,0),0) -> 0 | M53: {=IF(K53<-Sheet1!$H$2,IF(Sheet1!$A$2+SUMPRODUCT($F$2:F52,$N$2:N52)-SUMPRODUCT($F$2:F52,$M$2:M52)-$F$3*Sheet1!$L$2>=0,Sheet1!$L$2,0),0)} -> 0 | N53: =IF(K53>Sheet1!$G$2,IF(Sheet1!$B$2+SUM($M$2:M52)-SUM($N$2:N52)-Sheet1!$K$2>=0,Sheet1!$K$2,0),0) -> 0 | O53: =IF(M53=0,"",F53) | P53: =IF(N53=0,"",F53) | Q53: =IF(O53="",0,IF(M53*O53*Sheet1!$D$2<Sheet1!$E$2,Sheet1!$E$2,M53*O53*Sheet1!$D$2)) -> 0 | R53: =IF(P53="",0,IF(P53*N53*Sheet1!$D$2<Sheet1!$E$2,Sheet1!$E$2,P53*N53*Sheet1!$D$2)) -> 0
A54: 45966 | B54: 0.43194444 | C54: 2.328 | D54: 2.328 | E54: 2.326 | F54: 2.327 | G54: 1962653 | H54: 8434 | J54: =F54-F53 -> -0.001 | K54: =(F54-F53)/F53 -> -0.00042955326 | L54: =IF(K54>Sheet1!$G$2,IF(Sheet1!$B$2+SUM($M$2:M53)-Sheet1!$K$2>=0,Sheet1!$K$2,0),0) -> 0 | M54: {=IF(K54<-Sheet1!$H$2,IF(Sheet1!$A$2+SUMPRODUCT($F$2:F53,$N$2:N53)-SUMPRODUCT($F$2:F53,$M$2:M53)-$F$3*Sheet1!$L$2>=0,Sheet1!$L$2,0),0)} -> 0 | N54: =IF(K54>Sheet1!$G$2,IF(Sheet1!$B$2+SUM($M$2:M53)-SUM($N$2:N53)-Sheet1!$K$2>=0,Sheet1!$K$2,0),0) -> 0 | O54: =IF(M54=0,"",F54) | P54: =IF(N54=0,"",F54) | Q54: =IF(O54="",0,IF(M54*O54*Sheet1!$D$2<Sheet1!$E$2,Sheet1!$E$2,M54*O54*Sheet1!$D$2)) -> 0 | R54: =IF(P54="",0,IF(P54*N54*Sheet1!$D$2<Sheet1!$E$2,Sheet1!$E$2,P54*N54*Sheet1!$D$2)) -> 0
... A68: 45966 | B68: 0.44166667 | C68: 2.334 | D68: 2.334 | E68: 2.332 | F68: 2.333 | G68: 2806456 | H68: 12029 | J68: =F68-F67 -> -0.001 | K68: =(F68-F67)/F67 -> -0.00042844901 | L68: =IF(K68>Sheet1!$G$2,IF(Sheet1!$B$2+SUM($M$2:M67)-Sheet1!$K$2>=0,Sheet1!$K$2,0),0) -> 0 | M68: {=IF(K68<-Sheet1!$H$2,IF(Sheet1!$A$2+SUMPRODUCT($F$2:F67,$N$2:N67)-SUMPRODUCT($F$2:F67,$M$2:M67)-$F$3*Sheet1!$L$2>=0,Sheet1!$L$2,0),0)} -> 0 | N68: =IF(K68>Sheet1!$G$2,IF(Sheet1!$B$2+SUM($M$2:M67)-SUM($N$2:N67)-Sheet1!$K$2>=0,Sheet1!$K$2,0),0) -> 0 | O68: =IF(M68=0,"",F68) | P68: =IF(N68=0,"",F68) | Q68: =IF(O68="",0,IF(M68*O68*Sheet1!$D$2<Sheet1!$E$2,Sheet1!$E$2,M68*O68*Sheet1!$D$2)) -> 0 | R68: =IF(P68="",0,IF(P68*N68*Sheet1!$D$2<Sheet1!$E$2,Sheet1!$E$2,P68*N68*Sheet1!$D$2)) -> 0
A69: 45966 | B69: 0.44236111 | C69: 2.332 | D69: 2.334 | E69: 2.332 | F69: 2.334 | G69: 2393530 | H69: 10258 | J69: =F69-F68 -> 0.001 | K69: =(F69-F68)/F68 -> 0.00042863266 | M69: {=IF(K69<-Sheet1!$H$2,IF(Sheet1!$A$2+SUMPRODUCT($F$2:F68,$N$2:N68)-SUMPRODUCT($F$2:F68,$M$2:M68)-$F$3*Sheet1!$L$2>=0,Sheet1!$L$2,0),0)} -> 0 | N69: =IF(K69>Sheet1!$G$2,IF(Sheet1!$B$2+SUM($M$2:M68)-SUM($N$2:N68)-Sheet1!$K$2>=0,Sheet1!$K$2,0),0) -> 0 | O69: =IF(M69=0,"",F69) | P69: =IF(N69=0,"",F69) | Q69: =IF(O69="",0,IF(M69*O69*Sheet1!$D$2<Sheet1!$E$2,Sheet1!$E$2,M69*O69*Sheet1!$D$2)) -> 0 | R69: =IF(P69="",0,IF(P69*N69*Sheet1!$D$2<Sheet1!$E$2,Sheet1!$E$2,P69*N69*Sheet1!$D$2)) -> 0
A70: 45966 | B70: 0.44305556 | C70: 2.333 | D70: 2.337 | E70: 2.333 | F70: 2.336 | G70: 7684749 | H70: 32907 | J70: =F70-F69 -> 0.002 | K70: =(F70-F69)/F69 -> 0.00085689803 | M70: {=IF(K70<-Sheet1!$H$2,IF(Sheet1!$A$2+SUMPRODUCT($F$2:F69,$N$2:N69)-SUMPRODUCT($F$2:F69,$M$2:M69)-$F$3*Sheet1!$L$2>=0,Sheet1!$L$2,0),0)} -> 0 | N70: =IF(K70>Sheet1!$G$2,IF(Sheet1!$B$2+SUM($M$2:M69)-SUM($N$2:N69)-Sheet1!$K$2>=0,Sheet1!$K$2,0),0) -> 0 | O70: =IF(M70=0,"",F70) | P70: =IF(N70=0,"",F70) | Q70: =IF(O70="",0,IF(M70*O70*Sheet1!$D$2<Sheet1!$E$2,Sheet1!$E$2,M70*O70*Sheet1!$D$2)) -> 0 | R70: =IF(P70="",0,IF(P70*N70*Sheet1!$D$2<Sheet1!$E$2,Sheet1!$E$2,P70*N70*Sheet1!$D$2)) -> 0
A71: 45966 | B71: 0.44375 | C71: 2.336 | D71: 2.339 | E71: 2.336 | F71: 2.338 | G71: 4575097 | H71: 19573 | J71: =F71-F70 -> 0.002 | K71: =(F71-F70)/F70 -> 0.00085616438 | M71: {=IF(K71<-Sheet1!$H$2,IF(Sheet1!$A$2+SUMPRODUCT($F$2:F70,$N$2:N70)-SUMPRODUCT($F$2:F70,$M$2:M70)-$F$3*Sheet1!$L$2>=0,Sheet1!$L$2,0),0)} -> 0 | N71: =IF(K71>Sheet1!$G$2,IF(Sheet1!$B$2+SUM($M$2:M70)-SUM($N$2:N70)-Sheet1!$K$2>=0,Sheet1!$K$2,0),0) -> 0 | O71: =IF(M71=0,"",F71) | P71: =IF(N71=0,"",F71) | Q71: =IF(O71="",0,IF(M71*O71*Sheet1!$D$2<Sheet1!$E$2,Sheet1!$E$2,M71*O71*Sheet1!$D$2)) -> 0 | R71: =IF(P71="",0,IF(P71*N71*Sheet1!$D$2<Sheet1!$E$2,Sheet1!$E$2,P71*N71*Sheet1!$D$2)) -> 0
A72: 45966 | B72: 0.44444444 | C72: 2.338 | D72: 2.339 | E72: 2.337 | F72: 2.338 | G72: 2807889 | H72: 12010 | J72: =F72-F71 -> 0 | K72: =(F72-F71)/F71 -> 0 | M72: {=IF(K72<-Sheet1!$H$2,IF(Sheet1!$A$2+SUMPRODUCT($F$2:F71,$N$2:N71)-SUMPRODUCT($F$2:F71,$M$2:M71)-$F$3*Sheet1!$L$2>=0,Sheet1!$L$2,0),0)} -> 0 | N72: =IF(K72>Sheet1!$G$2,IF(Sheet1!$B$2+SUM($M$2:M71)-SUM($N$2:N71)-Sheet1!$K$2>=0,Sheet1!$K$2,0),0) -> 0 | O72: =IF(M72=0,"",F72) | P72: =IF(N72=0,"",F72) | Q72: =IF(O72="",0,IF(M72*O72*Sheet1!$D$2<Sheet1!$E$2,Sheet1!$E$2,M72*O72*Sheet1!$D$2)) -> 0 | R72: =IF(P72="",0,IF(P72*N72*Sheet1!$D$2<Sheet1!$E$2,Sheet1!$E$2,P72*N72*Sheet1!$D$2)) -> 0
A73: 45966 | B73: 0.44513889 | C73: 2.338 | D73: 2.338 | E73: 2.335 | F73: 2.336 | G73: 3383010 | H73: 14476 | J73: =F73-F72 -> -0.002 | K73: =(F73-F72)/F72 -> -0.00085543199 | M73: {=IF(K73<-Sheet1!$H$2,IF(Sheet1!$A$2+SUMPRODUCT($F$2:F72,$N$2:N72)-SUMPRODUCT($F$2:F72,$M$2:M72)-$F$3*Sheet1!$L$2>=0,Sheet1!$L$2,0),0)} -> 0 | N73: =IF(K73>Sheet1!$G$2,IF(Sheet1!$B$2+SUM($M$2:M72)-SUM($N$2:N72)-Sheet1!$K$2>=0,Sheet1!$K$2,0),0) -> 0 | O73: =IF(M73=0,"",F73) | P73: =IF(N73=0,"",F73) | Q73: =IF(O73="",0,IF(M73*O73*Sheet1!$D$2<Sheet1!$E$2,Sheet1!$E$2,M73*O73*Sheet1!$D$2)) -> 0 | R73: =IF(P73="",0,IF(P73*N73*Sheet1!$D$2<Sheet1!$E$2,Sheet1!$E$2,P73*N73*Sheet1!$D$2)) -> 0
A74: 45966 | B74: 0.44583333 | C74: 2.336 | D74: 2.336 | E74: 2.335 | F74: 2.335 | G74: 2857591 | H74: 12235 | J74: =F74-F73 -> -0.001 | K74: =(F74-F73)/F73 -> -0.00042808219 | M74: {=IF(K74<-Sheet1!$H$2,IF(Sheet1!$A$2+SUMPRODUCT($F$2:F73,$N$2:N73)-SUMPRODUCT($F$2:F73,$M$2:M73)-$F$3*Sheet1!$L$2>=0,Sheet1!$L$2,0),0)} -> 0 | N74: =IF(K74>Sheet1!$G$2,IF(Sheet1!$B$2+SUM($M$2:M73)-SUM($N$2:N73)-Sheet1!$K$2>=0,Sheet1!$K$2,0),0) -> 0 | O74: =IF(M74=0,"",F74) | P74: =IF(N74=0,"",F74) | Q74: =IF(O74="",0,IF(M74*O74*Sheet1!$D$2<Sheet1!$E$2,Sheet1!$E$2,M74*O74*Sheet1!$D$2)) -> 0 | R74: =IF(P74="",0,IF(P74*N74*Sheet1!$D$2<Sheet1!$E$2,Sheet1!$E$2,P74*N74*Sheet1!$D$2)) -> 0
A75: 45966 | B75: 0.44652778 | C75: 2.335 | D75: 2.337 | E75: 2.335 | F75: 2.337 | G75: 3221994 | H75: 13794 | J75: =F75-F74 -> 0.002 | K75: =(F75-F74)/F74 -> 0.00085653105 | M75: {=IF(K75<-Sheet1!$H$2,IF(Sheet1!$A$2+SUMPRODUCT($F$2:F74,$N$2:N74)-SUMPRODUCT($F$2:F74,$M$2:M74)-$F$3*Sheet1!$L$2>=0,Sheet1!$L$2,0),0)} -> 0 | N75: =IF(K75>Sheet1!$G$2,IF(Sheet1!$B$2+SUM($M$2:M74)-SUM($N$2:N74)-Sheet1!$K$2>=0,Sheet1!$K$2,0),0) -> 0 | O75: =IF(M75=0,"",F75) | P75: =IF(N75=0,"",F75) | Q75: =IF(O75="",0,IF(M75*O75*Sheet1!$D$2<Sheet1!$E$2,Sheet1!$E$2,M75*O75*Sheet1!$D$2)) -> 0 | R75: =IF(P75="",0,IF(P75*N75*Sheet1!$D$2<Sheet1!$E$2,Sheet1!$E$2,P75*N75*Sheet1!$D$2)) -> 0
A76: 45966 | B76: 0.44722222 | C76: 2.337 | D76: 2.339 | E76: 2.337 | F76: 2.339 | G76: 5086550 | H76: 21755 | J76: =F76-F75 -> 0.002 | K76: =(F76-F75)/F75 -> 0.00085579803 | M76: {=IF(K76<-Sheet1!$H$2,IF(Sheet1!$A$2+SUMPRODUCT($F$2:F75,$N$2:N75)-SUMPRODUCT($F$2:F75,$M$2:M75)-$F$3*Sheet1!$L$2>=0,Sheet1!$L$2,0),0)} -> 0 | N76: =IF(K76>Sheet1!$G$2,IF(Sheet1!$B$2+SUM($M$2:M75)-SUM($N$2:N75)-Sheet1!$K$2>=0,Sheet1!$K$2,0),0) -> 0 | O76: =IF(M76=0,"",F76) | P76: =IF(N76=0,"",F76) | Q76: =IF(O76="",0,IF(M76*O76*Sheet1!$D$2<Sheet1!$E$2,Sheet1!$E$2,M76*O76*Sheet1!$D$2)) -> 0 | R76: =IF(P76="",0,IF(P76*N76*Sheet1!$D$2<Sheet1!$E$2,Sheet1!$E$2,P76*N76*Sheet1!$D$2)) -> 0
A77: 45966 | B77: 0.44791667 | C77: 2.341 | D77: 2.345 | E77: 2.341 | F77: 2.343 | G77: 7601751 | H77: 32454 | J77: =F77-F76 -> 0.004 | K77: =(F77-F76)/F76 -> 0.0017101325 | M77: {=IF(K77<-Sheet1!$H$2,IF(Sheet1!$A$2+SUMPRODUCT($F$2:F76,$N$2:N76)-SUMPRODUCT($F$2:F76,$M$2:M76)-$F$3*Sheet1!$L$2>=0,Sheet1!$L$2,0),0)} -> 0 | N77: =IF(K77>Sheet1!$G$2,IF(Sheet1!$B$2+SUM($M$2:M76)-SUM($N$2:N76)-Sheet1!$K$2>=0,Sheet1!$K$2,0),0) -> 400 | O77: =IF(M77=0,"",F77) | P77: =IF(N77=0,"",F77) -> 2.343 | Q77: =IF(O77="",0,IF(M77*O77*Sheet1!$D$2<Sheet1!$E$2,Sheet1!$E$2,M77*O77*Sheet1!$D$2)) -> 0 | R77: =IF(P77="",0,IF(P77*N77*Sheet1!$D$2<Sheet1!$E$2,Sheet1!$E$2,P77*N77*Sheet1!$D$2)) -> 0.1
A78: 45966 | B78: 0.44861111 | C78: 2.343 | D78: 2.344 | E78: 2.342 | F78: 2.344 | G78: 2352503 | H78: 10039 | J78: =F78-F77 -> 0.001 | K78: =(F78-F77)/F77 -> 0.00042680324 | M78: {=IF(K78<-Sheet1!$H$2,IF(Sheet1!$A$2+SUMPRODUCT($F$2:F77,$N$2:N77)-SUMPRODUCT($F$2:F77,$M$2:M77)-$F$3*Sheet1!$L$2>=0,Sheet1!$L$2,0),0)} -> 0 | N78: =IF(K78>Sheet1!$G$2,IF(Sheet1!$B$2+SUM($M$2:M77)-SUM($N$2:N77)-Sheet1!$K$2>=0,Sheet1!$K$2,0),0) -> 0 | O78: =IF(M78=0,"",F78) | P78: =IF(N78=0,"",F78) | Q78: =IF(O78="",0,IF(M78*O78*Sheet1!$D$2<Sheet1!$E$2,Sheet1!$E$2,M78*O78*Sheet1!$D$2)) -> 0 | R78: =IF(P78="",0,IF(P78*N78*Sheet1!$D$2<Sheet1!$E$2,Sheet1!$E$2,P78*N78*Sheet1!$D$2)) -> 0
A79: 45966 | B79: 0.44930556 | C79: 2.344 | D79: 2.348 | E79: 2.344 | F79: 2.348 | G79: 3862542 | H79: 16464 | J79: =F79-F78 -> 0.004 | K79: =(F79-F78)/F78 -> 0.0017064846 | M79: {=IF(K79<-Sheet1!$H$2,IF(Sheet1!$A$2+SUMPRODUCT($F$2:F78,$N$2:N78)-SUMPRODUCT($F$2:F78,$M$2:M78)-$F$3*Sheet1!$L$2>=0,Sheet1!$L$2,0),0)} -> 0 | N79: =IF(K79>Sheet1!$G$2,IF(Sheet1!$B$2+SUM($M$2:M78)-SUM($N$2:N78)-Sheet1!$K$2>=0,Sheet1!$K$2,0),0) -> 400 | O79: =IF(M79=0,"",F79) | P79: =IF(N79=0,"",F79) -> 2.348 | Q79: =IF(O79="",0,IF(M79*O79*Sheet1!$D$2<Sheet1!$E$2,Sheet1!$E$2,M79*O79*Sheet1!$D$2)) -> 0 | R79: =IF(P79="",0,IF(P79*N79*Sheet1!$D$2<Sheet1!$E$2,Sheet1!$E$2,P79*N79*Sheet1!$D$2)) -> 0.1
A80: 45966 | B80: 0.45 | C80: 2.347 | D80: 2.349 | E80: 2.346 | F80: 2.347 | G80: 4387368 | H80: 18690 | J80: =F80-F79 -> -0.001 | K80: =(F80-F79)/F79 -> -0.00042589438 | M80: {=IF(K80<-Sheet1!$H$2,IF(Sheet1!$A$2+SUMPRODUCT($F$2:F79,$N$2:N79)-SUMPRODUCT($F$2:F79,$M$2:M79)-$F$3*Sheet1!$L$2>=0,Sheet1!$L$2,0),0)} -> 0 | N80: =IF(K80>Sheet1!$G$2,IF(Sheet1!$B$2+SUM($M$2:M79)-SUM($N$2:N79)-Sheet1!$K$2>=0,Sheet1!$K$2,0),0) -> 0 | O80: =IF(M80=0,"",F80) | P80: =IF(N80=0,"",F80) | Q80: =IF(O80="",0,IF(M80*O80*Sheet1!$D$2<Sheet1!$E$2,Sheet1!$E$2,M80*O80*Sheet1!$D$2)) -> 0 | R80: =IF(P80="",0,IF(P80*N80*Sheet1!$D$2<Sheet1!$E$2,Sheet1!$E$2,P80*N80*Sheet1!$D$2)) -> 0
...
